Workbook

Sheet Read Me
A1: Scaleezy - Mobile App Feature Checklist
A2: Every feature of the Scaleezy web app, for tracking what has been built in the mobile app.
A3: Prepared 19-Oct-2026 from the web app source code (frontend/src and the Django backend).
A5: Sheets
A6: Checklist | B6: One row per feature. Columns A-I describe the web feature; columns J-O (yellow) are for the mobile developer to fill in.
A7: Summary | B7: Progress per module. Calculated automatically from the Checklist - do not type in it.
A8: API Routes | B8: Every backend route and the checklist features that use it. Routes no web screen calls are listed with a note.
A10: How to fill it in (mobile developer)
A11: 1. Mobile status | B11: Pick from the list: Not started, In progress, Done, Blocked, Not applicable.
A12: 2. Priority | B12: High, Medium or Low - set by the product owner.
A13: 3. Assigned to / Notes | B13: Free text. Note anything that behaves differently from the web app.
A14: 4. Tested? / Tested on | B14: Yes once checked against the web app, with the date.
A15: Only edit | B15: The yellow columns (J-O). Columns A-I come from the web app; filter them, but do not change them.
A17: Example of a filled-in row
A18: ID | B18: ORD-004
A19: Feature | B19: Bucket chips New / In progress / Closed
A20: Priority | B20: High
A21: Mobile status | B21: Done
A22: Assigned to | B22: Ravi
A23: Developer notes | B23: Shown as a segmented control at the top of the list.
A24: Tested? / Tested on | B24: Yes / 24-Oct-2026
A26: "Needed in mobile app?" column (pre-filled)
A27: Yes | B27: A boutique staff screen feature - build it.
A28: Customer web page | B28: A public page the boutique's customers open (portal, order tracking). Decide whether the mobile app needs it.
A29: Server only (no screen) | B29: Runs on the server by itself (scheduled jobs, automatic messages). Nothing to build; pre-set to Not applicable.
A30: Web only (platform console) | B30: The platform owner's Superadmin console, not the boutique app. Pre-set to Not applicable.
A31: No - not in web app | B31: Recorded so it is not mistaken for a gap: the web app does not offer it (or its screen is not shown). Pre-set to Not applicable.
A33: Roles used in the "Who can use it" column
A34: Owner | B34: The boutique owner (signed up the boutique).
A35: Master / Designer | B35: Supervisors: run the floor / the design work.
A36: Production roles | B36: Tailor, Maggam Master, Karigar, Maggam Karigar, Packaging Staff, QC Staff.
A37: Admin task | B37: A staff member the owner handed extra tasks to (Staff > Roles & Permissions).
A39: Totals
A40: Features listed | B40: =COUNTA(Checklist!A2:A757) -> 756
A41: Needed in mobile (Yes) | B41: =COUNTIF(Checklist!I2:I757,"Yes") -> 663
A42: Done so far | B42: =COUNTIF(Checklist!K2:K757,"Done") -> 0
A44: Source
A45: Built by reading every screen of the web app and checking the result against all backend API routes. Each row cites its web source file and line, so the developer can open the exact code.

Sheet Checklist
A1: ID | B1: Module | C1: Screen | D1: Feature | E1: What it does (acceptance criteria) | F1: Who can use it (roles) | G1: API endpoint(s) | H1: Web source (file:line) | I1: Needed in mobile app? | J1: Priority | K1: Mobile status | L1: Assigned to | M1: Developer notes | N1: Tested? | O1: Tested on (date)
A2: AUTH-001 | B2: Login, Sign-up & Session | C2: Entry routing | D2: URL-based start screen | E2: App opens on Login by default. `?reset=<token>` opens Set New Password. `?register` (on a path with no slug) opens Signup. A single path segment matching [a-z0-9]+ (not "app") is read as the boutique shop slug. | F2: All | G2: client-only | H2: frontend/src/App.jsx:1585-1603 | I2: Yes | K2: Not started
A3: AUTH-002 | B3: Login, Sign-up & Session | C3: Shop-slug login (/<slug>) | D3: Boutique lookup by slug | E3: On /<slug> the app looks up the boutique, shows a loader until the lookup finishes, then shows the boutique name above the Scaleezy wordmark. The heading reads "Welcome back, <owner first name>". An unknown or inactive slug returns 404, which the client treats as null. | F3: All (unauthenticated) | G3: GET /api/auth/boutique/<slug>/ (crm_api/auth_views.py:378 BoutiqueBySlugView, throttled) | H3: frontend/src/App.jsx:1616-1633, 3837-3853; frontend/src/services/api.js:266 | I3: Yes | K3: Not started
A4: AUTH-003 | B4: Login, Sign-up & Session | C4: Boutique not found | D4: Not-found screen with recovery actions | E4: Shows "No active boutique uses the address /<slug>". Buttons: "Try another address" (opens Find Boutique, prefilled), "Register a boutique" (/app?register) and "Back to Home" (/). | F4: All | G4: client-only (uses result of GET /api/auth/boutique/<slug>/) | H4: frontend/src/App.jsx:3779-3800 | I4: Yes | K4: Not started
A5: AUTH-004 | B5: Login, Sign-up & Session | C5: Find your boutique | D5: Find a boutique by name or URL | E5: One field with a host/ prefix. Input is normalised: the last path segment is lowercased and non-[a-z0-9] characters are stripped. A live preview reads "Goes to host/<slug>". Empty input gives a validation error. A lookup miss shows "No active boutique signs in at /<slug>". A match redirects to /<shop_slug>. The button shows "Checking…" while busy. Back and "Register one" links go to Signup. | F5: All | G5: GET /api/auth/boutique/<slug>/ | H5: frontend/src/App.jsx:2812-2836, 3717-3777 | I5: Yes | K5: Not started
A6: AUTH-005 | B6: Login, Sign-up & Session | C6: Login | D6: Email/username + password sign-in | E6: Email and password are required; empty fields trigger the alert "Please fill in all credentials". The shop_slug from the URL is sent as a tenant hint. Double-submit is blocked by a busy flag and the button reads "Signing in…". Server errors show in an inline alert: invalid credentials, suspended boutique (403 "access has been suspended"), throttling, or the 503 maintenance message. On success the token and tenant_id are saved to localStorage. | F6: All | G6: POST /api/auth/login/ {username,password,shop_slug} (crm_api/auth_views.py:407 LoginView) | H6: frontend/src/App.jsx:2782-2809, 3856-3915; frontend/src/services/api.js:212-235 | I6: Yes | K6: Not started
A7: AUTH-006 | B7: Login, Sign-up & Session | C7: Login | D7: Show/hide password toggle | E7: Eye icon switches the password field between text and password. | F7: All | G7: client-only | H7: frontend/src/App.jsx:3884-3890 | I7: Yes | K7: Not started
A8: AUTH-007 | B8: Login, Sign-up & Session | C8: Login | D8: Post-signup login copy | E8: After a fresh registration that returned no token, the heading becomes "Your boutique is ready" with "Sign in with the email and password you just created". | F8: Owner | G8: client-only | H8: frontend/src/App.jsx:3853-3854 | I8: Yes | K8: Not started
A9: AUTH-008 | B9: Login, Sign-up & Session | C9: Login | D9: Back to Home / Register links | E9: "Back to Home" goes to /. "Register a boutique" goes to /app?register. | F9: All | G9: client-only | H9: frontend/src/App.jsx:3806-3831, 3917-3922 | I9: Yes | K9: Not started
A10: AUTH-009 | B10: Login, Sign-up & Session | C10: Login | D10: Role resolution after login | E10: Server role comes from resolve_user_role: superuser or tenant owner_email = Owner; tailor_profile.role = production role; designer_profile = Designer; anything else = no role. Landing tab: Designer goes to Designs (requests view); production roles including Master go to My work; Owner and others go to Overview. The user payload carries role, modules, module_groups, admin_tasks, design_system, color_mode, shop_slug, profile_photo, tailor_id and designer_id. | F10: All | G10: POST /api/auth/login/ → user_payload (crm_api/auth_views.py:79-173; core/roles.py:50) | H10: frontend/src/App.jsx:2796-2803 | I10: Yes | K10: Not started
A11: AUTH-010 | B11: Login, Sign-up & Session | C11: Login | D11: URL normalised to the boutique slug | E11: After login or session restore, the address bar is rewritten to /<shop_slug> using history.replaceState. | F11: All | G11: client-only | H11: frontend/src/App.jsx:1636-1641 | I11: Yes | K11: Not started
A12: AUTH-011 | B12: Login, Sign-up & Session | C12: Login | D12: Tenant theme applied at sign-in | E12: design_system (scaleezy/atelier) and color_mode from the user payload are applied and stored. A personal mode picked in Settings on this device takes precedence. | F12: All | G12: client-only (from /auth/login or /auth/me payload) | H12: frontend/src/App.jsx:1614; frontend/src/theme.js:82-88 | I12: Yes | K12: Not started
A13: AUTH-012 | B13: Login, Sign-up & Session | C13: Forgot password | D13: Request reset link | E13: Reached from "Forgot password?" on Login, with the email prefilled. Empty email is rejected. The server answers identically whether or not the account exists. Confirmation reads "If <email> has an account, a reset link is on its way… stops working in an hour… check spam". Includes Back to sign in. The button shows "Sending…" while busy. | F13: All | G13: POST /api/auth/password-reset/ {email} (crm_api/auth_views.py:543, throttled) | H13: frontend/src/App.jsx:2354-2371, 3896-3903, 3932-3977 | I13: Yes | K13: Not started
... A172: PAY-006 | B172: Orders - Payments | C172: Invoices & Billing | D172: View Invoice | E172: Opens the invoice modal for the order. | F172: Owner, Admin task orders.invoices | G172: client-only | H172: frontend/src/App.jsx:6515 | I172: Yes | K172: Not started
A173: PAY-007 | B173: Orders - Payments | D173: Discounts after order | E173: No discount editor after placement. Discount is set only in the wizard. Backend PATCH accepts discount (admin task orders.discounts). | F173: Owner (wizard) | G173: PATCH /api/orders/{id}/ (not wired) | H173: core/admin_access.py:30 | I173: No - not in web app | K173: Not applicable
A174: OINV-001 | B174: Orders - Invoice | C174: Invoice modal | D174: Render & print invoice | E174: Renders with the order's invoice_template (or boutique default, classic/modern/elegant) using order + boutique settings (logo, phone, terms). 'Print Invoice' calls window.print with a print-only stylesheet (save-as-PDF is the 'download' route; no separate download API). Close. | F174: Owner, Admin, counter staff after confirm | G174: client-only | H174: frontend/src/App.jsx:9056, frontend/src/components/invoice/InvoiceTemplates.jsx:629 | I174: Yes | K174: Not started
A175: OINV-002 | B175: Orders - Invoice | C175: Settings › Invoice template | D175: Choose invoice template | E175: Owner picks Classic / Modern / Elegant with carousel previews and a full preview modal. Saved as the boutique default. | F175: Owner | G175: GET/PATCH /api/settings/invoice-template/ (crm_api/invoice_views.py:17) | H175: frontend/src/components/invoice/InvoiceTemplateSelector.jsx:29 | I175: Yes | K175: Not started
A176: VOICE-001 | B176: Voice Notes | C176: Shared components | D176: Voice dictation (VoiceTextarea) | E176: Mic button on textareas: browser speech-to-text in the app language (falls back to recording if unsupported). Used in comments, issues and notes. | F176: All | G176: client-only | H176: frontend/src/components/ui/VoiceTextarea.jsx:25 | I176: Yes | K176: Not started
A177: VOICE-002 | B177: Voice Notes | C177: Shared components | D177: Voice note recorder | E177: Idle → Recording (timer, auto-stop at 180 s, red Stop) → Preview (play) → Send / Discard. Sent: player plus Delete. 'This browser cannot record audio' error. Upload returns a media URL. | F177: All | G177: POST /api/voice-notes/ (multipart audio) | H177: frontend/src/components/ui/VoiceTextarea.jsx:207 | I177: Yes | K177: Not started
A178: VOICE-003 | B178: Voice Notes | C178: Shared components | D178: Read aloud (SpeakButton) | E178: Text-to-speech toggle on notes and tailor comments. | F178: All | G178: client-only | H178: frontend/src/components/ui/VoiceTextarea.jsx:350 | I178: Yes | K178: Not started
A179: ALT-001 | B179: Alterations | C179: Outside garment intake modal | D179: Take in outside garment | E179: Customer: existing, or '+ New customer (walk-in)' with first name (required), last name and 10-digit mobile (validated; country code stripped). Garment type from templates, or 'Other' + description (one of them required). Garment details, optional arrival photo (camera/upload), issue size Small/Big, customer request and adjustments (dictation), charge (validated), notes. Always paid. Creates an alteration order and uploads the photo as its FRONT garment image. | F179: Owner, Master, Admin task workshop.alterations | G179: POST /api/customers/ (new) → POST /api/orders/outside-alteration/ (crm_api/views.py:1327) → POST /api/orders/{id}/garment-images/ | H179: frontend/src/features/alterations/OutsideGarmentIntake.jsx:26 | I179: Yes | K179: Not started
A180: IPRD-001 | B180: Internal Production (Boutique Stock) | C180: Stitch for the boutique dialog | D180: Start internal production run | E180: Opened from the service selector. Fields: what (template, required), how many (integer 1-50), full garment configurator, Master, Tailor, urgency (Normal / Soon / Rush / Whenever), wanted-by date, notes. No customer, price or payment. Garments go to inventory stock when finished. The order shows a 'Boutique stock' badge. | F180: Owner | G180: POST /api/orders/internal-production/ (crm_api/views.py:641) | H180: frontend/src/features/production/BoutiqueProduction.jsx:30, frontend/src/App.jsx:7446 | I180: Yes | K180: Not started
A181: IPRD-002 | B181: Internal Production (Boutique Stock) | C181: Garment configurator | D181: Configure garment for stock run | E181: One panel: required/conditional spec fields, production notes, 'More details' optional fields, the look part by part (catalogue picker), fabric from stock (slot picker + quantities), trims & accessories, 'To buy for this run' purchases, measurements. | F181: Owner | G181: GET /api/catalog/templates/{key}/, GET /api/inventory/items/?picker=true, GET /api/design-studio/assets/ | H181: frontend/src/features/production/GarmentConfigurator.jsx:34 | I181: Yes | K181: Not started
A182: WIZ-001 | B182: New Order Wizard | C182: New order selector (view 'order-selector') | D182: Resume saved drafts list | E182: Card listing open drafts: customer name (or garments / 'Unnamed customer'), garments, 'Step x of y', last saved time. Resume rehydrates the wizard at the saved step and garment. | F182: Owner, Admin task orders.create (anyone who can create orders) | G182: GET /api/order-drafts/ (crm_api/views.py:2302) | H182: frontend/src/App.jsx:7353, frontend/src/App.jsx:2068 | I182: Yes | K182: Not started
A183: WIZ-002 | B183: New Order Wizard | C183: New order selector | D183: Discard draft | E183: Two-step confirm ('Discard this order? … everything entered will be lost' → Keep it / Discard permanently). | F183: Owner, Admin task orders.create | G183: DELETE /api/order-drafts/{id}/ (crm_api/views.py:2337) | H183: frontend/src/App.jsx:7386 | I183: Yes | K183: Not started
A184: WIZ-003 | B184: New Order Wizard | C184: New order selector | D184: Service choice | E184: Stitch something / Alter a garment (disabled for Designer) / Design something new / Stitch for the boutique (Owner only). Each starts a clean wizard. | F184: Owner, Designer, Master, Admin | G184: client-only | H184: frontend/src/App.jsx:7428, frontend/src/App.jsx:2934 | I184: Yes | K184: Not started
A185: WIZ-004 | B185: New Order Wizard | C185: Wizard header | D185: Autosave status & close | E185: 'Autosaves every minute' / Saving / Saved / Could not save / Conflict (changed in another tab). Saves every 60 s and on tab hide. Disabled for alterations and after a conflict. The ✕ close saves the draft first (if anything was entered), then returns to the dashboard. | F185: Owner, Admin task orders.create | G185: POST /api/order-drafts/ (first) / PATCH /api/order-drafts/{id}/ {payload, current_step, customer, version} (409 on conflict) | H185: frontend/src/App.jsx:7479, frontend/src/App.jsx:3401, frontend/src/App.jsx:2161, frontend/src/App.jsx:3032 | I185: Yes | K185: Not started
... A757: SA-049 | B757: Superadmin Console (Platform) | C757: Automatic (server) | D757: Sign-in attempt recording | E757: Boutique logins, console logins and password-reset requests logged with IP/agent; suspicious thresholds (20 fails/IP/hour, 10 per account, IP across 3 boutiques, 5 console fails) | F757: System | G757: POST /api/auth/login/ ; /api/auth/password-reset/ ; /api/superadmin/auth/login/ | H757: superadmin/signins.py:21 | I757: Web only (platform console) | K757: Not applicable

Sheet Summary
A1: Mobile app progress by module
A2: Counts update automatically from the Checklist sheet (column K "Mobile status").
A4: Module | B4: Features | C4: Not started | D4: In progress | E4: Done | F4: Blocked | G4: Not applicable | H4: To build (excl. not applicable) | I4: % done
A5: Login, Sign-up & Session | B5: =COUNTIFS(Checklist!$B$2:$B$757,$A5) -> 25 | C5: =COUNTIFS(Checklist!$B$2:$B$757,$A5,Checklist!$K$2:$K$757,"Not started") -> 25 | D5: =COUNTIFS(Checklist!$B$2:$B$757,$A5,Checklist!$K$2:$K$757,"In progress") -> 0 | E5: =COUNTIFS(Checklist!$B$2:$B$757,$A5,Checklist!$K$2:$K$757,"Done") -> 0 | F5: =COUNTIFS(Checklist!$B$2:$B$757,$A5,Checklist!$K$2:$K$757,"Blocked") -> 0 | G5: =COUNTIFS(Checklist!$B$2:$B$757,$A5,Checklist!$K$2:$K$757,"Not applicable") -> 0 | H5: =B5-G5 -> 25 | I5: =IF(H5=0,"-",E5/H5) -> 0
A6: Navigation & App Shell | B6: =COUNTIFS(Checklist!$B$2:$B$757,$A6) -> 26 | C6: =COUNTIFS(Checklist!$B$2:$B$757,$A6,Checklist!$K$2:$K$757,"Not started") -> 25 | D6: =COUNTIFS(Checklist!$B$2:$B$757,$A6,Checklist!$K$2:$K$757,"In progress") -> 0 | E6: =COUNTIFS(Checklist!$B$2:$B$757,$A6,Checklist!$K$2:$K$757,"Done") -> 0 | F6: =COUNTIFS(Checklist!$B$2:$B$757,$A6,Checklist!$K$2:$K$757,"Blocked") -> 0 | G6: =COUNTIFS(Checklist!$B$2:$B$757,$A6,Checklist!$K$2:$K$757,"Not applicable") -> 1 | H6: =B6-G6 -> 25 | I6: =IF(H6=0,"-",E6/H6) -> 0
A7: Dashboard (Overview) | B7: =COUNTIFS(Checklist!$B$2:$B$757,$A7) -> 15 | C7: =COUNTIFS(Checklist!$B$2:$B$757,$A7,Checklist!$K$2:$K$757,"Not started") -> 15 | D7: =COUNTIFS(Checklist!$B$2:$B$757,$A7,Checklist!$K$2:$K$757,"In progress") -> 0 | E7: =COUNTIFS(Checklist!$B$2:$B$757,$A7,Checklist!$K$2:$K$757,"Done") -> 0 | F7: =COUNTIFS(Checklist!$B$2:$B$757,$A7,Checklist!$K$2:$K$757,"Blocked") -> 0 | G7: =COUNTIFS(Checklist!$B$2:$B$757,$A7,Checklist!$K$2:$K$757,"Not applicable") -> 0 | H7: =B7-G7 -> 15 | I7: =IF(H7=0,"-",E7/H7) -> 0
A8: Appointments | B8: =COUNTIFS(Checklist!$B$2:$B$757,$A8) -> 12 | C8: =COUNTIFS(Checklist!$B$2:$B$757,$A8,Checklist!$K$2:$K$757,"Not started") -> 12 | D8: =COUNTIFS(Checklist!$B$2:$B$757,$A8,Checklist!$K$2:$K$757,"In progress") -> 0 | E8: =COUNTIFS(Checklist!$B$2:$B$757,$A8,Checklist!$K$2:$K$757,"Done") -> 0 | F8: =COUNTIFS(Checklist!$B$2:$B$757,$A8,Checklist!$K$2:$K$757,"Blocked") -> 0 | G8: =COUNTIFS(Checklist!$B$2:$B$757,$A8,Checklist!$K$2:$K$757,"Not applicable") -> 0 | H8: =B8-G8 -> 12 | I8: =IF(H8=0,"-",E8/H8) -> 0
A9: Orders - List | B9: =COUNTIFS(Checklist!$B$2:$B$757,$A9) -> 23 | C9: =COUNTIFS(Checklist!$B$2:$B$757,$A9,Checklist!$K$2:$K$757,"Not started") -> 23 | D9: =COUNTIFS(Checklist!$B$2:$B$757,$A9,Checklist!$K$2:$K$757,"In progress") -> 0 | E9: =COUNTIFS(Checklist!$B$2:$B$757,$A9,Checklist!$K$2:$K$757,"Done") -> 0 | F9: =COUNTIFS(Checklist!$B$2:$B$757,$A9,Checklist!$K$2:$K$757,"Blocked") -> 0 | G9: =COUNTIFS(Checklist!$B$2:$B$757,$A9,Checklist!$K$2:$K$757,"Not applicable") -> 0 | H9: =B9-G9 -> 23 | I9: =IF(H9=0,"-",E9/H9) -> 0
A10: Orders - Detail | B10: =COUNTIFS(Checklist!$B$2:$B$757,$A10) -> 40 | C10: =COUNTIFS(Checklist!$B$2:$B$757,$A10,Checklist!$K$2:$K$757,"Not started") -> 39 | D10: =COUNTIFS(Checklist!$B$2:$B$757,$A10,Checklist!$K$2:$K$757,"In progress") -> 0 | E10: =COUNTIFS(Checklist!$B$2:$B$757,$A10,Checklist!$K$2:$K$757,"Done") -> 0 | F10: =COUNTIFS(Checklist!$B$2:$B$757,$A10,Checklist!$K$2:$K$757,"Blocked") -> 0 | G10: =COUNTIFS(Checklist!$B$2:$B$757,$A10,Checklist!$K$2:$K$757,"Not applicable") -> 1 | H10: =B10-G10 -> 39 | I10: =IF(H10=0,"-",E10/H10) -> 0
A11: Orders - Workflow Stages | B11: =COUNTIFS(Checklist!$B$2:$B$757,$A11) -> 24 | C11: =COUNTIFS(Checklist!$B$2:$B$757,$A11,Checklist!$K$2:$K$757,"Not started") -> 24 | D11: =COUNTIFS(Checklist!$B$2:$B$757,$A11,Checklist!$K$2:$K$757,"In progress") -> 0 | E11: =COUNTIFS(Checklist!$B$2:$B$757,$A11,Checklist!$K$2:$K$757,"Done") -> 0 | F11: =COUNTIFS(Checklist!$B$2:$B$757,$A11,Checklist!$K$2:$K$757,"Blocked") -> 0 | G11: =COUNTIFS(Checklist!$B$2:$B$757,$A11,Checklist!$K$2:$K$757,"Not applicable") -> 0 | H11: =B11-G11 -> 24 | I11: =IF(H11=0,"-",E11/H11) -> 0
A12: Orders - Payments | B12: =COUNTIFS(Checklist!$B$2:$B$757,$A12) -> 7 | C12: =COUNTIFS(Checklist!$B$2:$B$757,$A12,Checklist!$K$2:$K$757,"Not started") -> 6 | D12: =COUNTIFS(Checklist!$B$2:$B$757,$A12,Checklist!$K$2:$K$757,"In progress") -> 0 | E12: =COUNTIFS(Checklist!$B$2:$B$757,$A12,Checklist!$K$2:$K$757,"Done") -> 0 | F12: =COUNTIFS(Checklist!$B$2:$B$757,$A12,Checklist!$K$2:$K$757,"Blocked") -> 0 | G12: =COUNTIFS(Checklist!$B$2:$B$757,$A12,Checklist!$K$2:$K$757,"Not applicable") -> 1 | H12: =B12-G12 -> 6 | I12: =IF(H12=0,"-",E12/H12) -> 0
A13: Orders - Invoice | B13: =COUNTIFS(Checklist!$B$2:$B$757,$A13) -> 2 | C13: =COUNTIFS(Checklist!$B$2:$B$757,$A13,Checklist!$K$2:$K$757,"Not started") -> 2 | D13: =COUNTIFS(Checklist!$B$2:$B$757,$A13,Checklist!$K$2:$K$757,"In progress") -> 0 | E13: =COUNTIFS(Checklist!$B$2:$B$757,$A13,Checklist!$K$2:$K$757,"Done") -> 0 | F13: =COUNTIFS(Checklist!$B$2:$B$757,$A13,Checklist!$K$2:$K$757,"Blocked") -> 0 | G13: =COUNTIFS(Checklist!$B$2:$B$757,$A13,Checklist!$K$2:$K$757,"Not applicable") -> 0 | H13: =B13-G13 -> 2 | I13: =IF(H13=0,"-",E13/H13) -> 0
A14: Voice Notes | B14: =COUNTIFS(Checklist!$B$2:$B$757,$A14) -> 3 | C14: =COUNTIFS(Checklist!$B$2:$B$757,$A14,Checklist!$K$2:$K$757,"Not started") -> 3 | D14: =COUNTIFS(Checklist!$B$2:$B$757,$A14,Checklist!$K$2:$K$757,"In progress") -> 0 | E14: =COUNTIFS(Checklist!$B$2:$B$757,$A14,Checklist!$K$2:$K$757,"Done") -> 0 | F14: =COUNTIFS(Checklist!$B$2:$B$757,$A14,Checklist!$K$2:$K$757,"Blocked") -> 0 | G14: =COUNTIFS(Checklist!$B$2:$B$757,$A14,Checklist!$K$2:$K$757,"Not applicable") -> 0 | H14: =B14-G14 -> 3 | I14: =IF(H14=0,"-",E14/H14) -> 0
A15: Alterations | B15: =COUNTIFS(Checklist!$B$2:$B$757,$A15) -> 1 | C15: =COUNTIFS(Checklist!$B$2:$B$757,$A15,Checklist!$K$2:$K$757,"Not started") -> 1 | D15: =COUNTIFS(Checklist!$B$2:$B$757,$A15,Checklist!$K$2:$K$757,"In progress") -> 0 | E15: =COUNTIFS(Checklist!$B$2:$B$757,$A15,Checklist!$K$2:$K$757,"Done") -> 0 | F15: =COUNTIFS(Checklist!$B$2:$B$757,$A15,Checklist!$K$2:$K$757,"Blocked") -> 0 | G15: =COUNTIFS(Checklist!$B$2:$B$757,$A15,Checklist!$K$2:$K$757,"Not applicable") -> 0 | H15: =B15-G15 -> 1 | I15: =IF(H15=0,"-",E15/H15) -> 0
A16: Internal Production (Boutique Stock) | B16: =COUNTIFS(Checklist!$B$2:$B$757,$A16) -> 2 | C16: =COUNTIFS(Checklist!$B$2:$B$757,$A16,Checklist!$K$2:$K$757,"Not started") -> 2 | D16: =COUNTIFS(Checklist!$B$2:$B$757,$A16,Checklist!$K$2:$K$757,"In progress") -> 0 | E16: =COUNTIFS(Checklist!$B$2:$B$757,$A16,Checklist!$K$2:$K$757,"Done") -> 0 | F16: =COUNTIFS(Checklist!$B$2:$B$757,$A16,Checklist!$K$2:$K$757,"Blocked") -> 0 | G16: =COUNTIFS(Checklist!$B$2:$B$757,$A16,Checklist!$K$2:$K$757,"Not applicable") -> 0 | H16: =B16-G16 -> 2 | I16: =IF(H16=0,"-",E16/H16) -> 0
... A42: Superadmin Console (Platform) | B42: =COUNTIFS(Checklist!$B$2:$B$757,$A42) -> 49 | C42: =COUNTIFS(Checklist!$B$2:$B$757,$A42,Checklist!$K$2:$K$757,"Not started") -> 0 | D42: =COUNTIFS(Checklist!$B$2:$B$757,$A42,Checklist!$K$2:$K$757,"In progress") -> 0 | E42: =COUNTIFS(Checklist!$B$2:$B$757,$A42,Checklist!$K$2:$K$757,"Done") -> 0 | F42: =COUNTIFS(Checklist!$B$2:$B$757,$A42,Checklist!$K$2:$K$757,"Blocked") -> 0 | G42: =COUNTIFS(Checklist!$B$2:$B$757,$A42,Checklist!$K$2:$K$757,"Not applicable") -> 49 | H42: =B42-G42 -> 0 | I42: =IF(H42=0,"-",E42/H42) -> -
A43: All modules | B43: =SUM(B5:B42) -> 756 | C43: =SUM(C5:C42) -> 682 | D43: =SUM(D5:D42) -> 0 | E43: =SUM(E5:E42) -> 0 | F43: =SUM(F5:F42) -> 0 | G43: =SUM(G5:G42) -> 74 | H43: =SUM(H5:H42) -> 682 | I43: =IF(H43=0,"-",E43/H43) -> 0

Sheet API Routes
A1: Every backend API route, and which checklist features use it
A2: Generated from the Django URL configuration. "Used by the web app?" = No means no screen the web app shows calls it today; the Note says why.
A4: Route | B4: Django view | C4: Methods / actions | D4: Used by the web app? | E4: Checklist IDs | F4: Note
A5: /media/(?P<path>.*) | B5: serve | C5: (all methods) | D5: No | F5: Serves uploaded files (photos, voice notes) during development.
A6: /api/ | B6: APIRootView | C6: (all methods) | D6: Yes | E6: AUTH-021
A7: /api/boutique-designs/ | B7: BoutiqueDesignViewSet | C7: get:list, post:create | D7: Yes | E7: DES-029, DES-030, NAV-022
A8: /api/boutique-designs/(?P<pk>[/.]+)/ | B8: BoutiqueDesignViewSet | C8: get:retrieve, put:update, patch:partial_update, delete:destroy | D8: Yes | E8: DES-029, DES-030, NAV-022
A9: /api/boutique-designs/upload-image/ | B9: BoutiqueDesignViewSet | C9: post:upload_image | D9: Yes | E9: DES-011, DES-029, STF-020
A10: /api/boutique-settings/ | B10: BoutiqueSettingsViewSet | C10: get:list, post:create | D10: Yes | E10: ACC-004, ACC-005, ACC-006, ACC-007, ACC-008, ACC-009, ACC-010, ATT-006, DES-025, NAV-022, SET-003, SET-017
A11: /api/boutique-settings/admin-access/ | B11: BoutiqueSettingsViewSet | C11: get:admin_access, put:admin_access | D11: Yes | E11: PERM-001, PERM-003, SET-013, SET-015
A12: /api/boutique-settings/role-modules/ | B12: BoutiqueSettingsViewSet | C12: get:role_modules, patch:role_modules | D12: Yes | E12: PERM-005, SET-016
A13: /api/customers/ | B13: CustomerViewSet | C13: get:list, post:create | D13: Yes | E13: ALT-001, ANL-005, CUS-002, CUS-018, CUS-020, CUS-021, CUS-024, CUS-025, CUS-032, CUS-034, CUS-035, CUS-043 ...
A14: /api/customers/(?P<pk>[/.]+)/ | B14: CustomerViewSet | C14: get:retrieve, put:update, patch:partial_update, delete:destroy | D14: Yes | E14: ALT-001, ANL-005, CUS-002, CUS-018, CUS-020, CUS-021, CUS-024, CUS-025, CUS-032, CUS-034, CUS-035, CUS-043 ...
A15: /api/customers/(?P<pk>[/.]+)/ai-suggestions/ | B15: CustomerViewSet | C15: get:ai_suggestions | D15: Yes | E15: CUS-051
A16: /api/customers/(?P<pk>[/.]+)/boutique-designs/ | B16: CustomerViewSet | C16: get:boutique_designs | D16: Yes | E16: CUS-051
A17: /api/customers/(?P<pk>[/.]+)/create-order/ | B17: CustomerViewSet | C17: post:create_order | D17: Yes | E17: CUS-051
... A47: /api/orders/(?P<pk>[/.]+)/stage-seen/ | B47: OrderViewSet | C47: post:stage_seen | D47: Yes | E47: CUS-026, STG-002, WORK-022
A48: /api/orders/(?P<pk>[/.]+)/submit-completion/ | B48: OrderViewSet | C48: patch:submit_completion | D48: No | F48: Exists on the server, but no screen in the web app calls it.
A49: /api/orders/(?P<pk>[/.]+)/submit-stage-review/ | B49: OrderViewSet | C49: post:submit_stage_review | D49: No | F49: Exists on the server, but no screen in the web app calls it.
A50: /api/orders/(?P<pk>[/.]+)/transition/ | B50: OrderViewSet | C50: post:transition_stage | D50: Yes | E50: ATT-016, ORD-023, STG-014, STG-015, STG-016, STG-017, STG-018, STG-019, STG-020, STG-023, WORK-014, WORK-015 ...
A51: /api/orders/(?P<pk>[/.]+)/update-status/ | B51: OrderViewSet | C51: patch:update_status | D51: Yes | E51: STG-024
A52: /api/orders/assignable-staff/ | B52: OrderViewSet | C52: get:assignable_staff | D52: Yes | E52: DES-039, WORK-020
A53: /api/orders/customer-messages/ | B53: OrderViewSet | C53: get:customer_messages | D53: Yes | E53: AUTO-004, NAV-022, ODT-017, SET-018
A54: /api/orders/internal-production/ | B54: OrderViewSet | C54: post:internal_production | D54: Yes | E54: IPRD-001, PROD-004
A55: /api/orders/outside-alteration/ | B55: OrderViewSet | C55: post:outside_alteration | D55: Yes | E55: ALT-001
A56: /api/tailors/ | B56: TailorViewSet | C56: get:list, post:create | D56: Yes | E56: ANL-009, ATT-008, NAV-022, PERM-001, PROD-003, SET-013, STF-005, STF-019, STF-027
A57: /api/tailors/(?P<pk>[/.]+)/ | B57: TailorViewSet | C57: get:retrieve, put:update, patch:partial_update, delete:destroy | D57: Yes | E57: ANL-009, ATT-008, NAV-022, PERM-001, PROD-003, SET-013, STF-005, STF-019, STF-027
A58: /api/tailors/(?P<pk>[/.]+)/reset-password/ | B58: TailorViewSet | C58: post:reset_password | D58: Yes | E58: AUTH-025, STF-026
A59: /api/activities/ | B59: APIRootView | C59: (all methods) | D59: No | F59: Framework index page, not a feature.
A60: /api/activities/activities/ | B60: UniversalActivityViewSet | C60: get:list | D60: Yes | E60: ACT-003
A61: /api/activities/activities/(?P<pk>[/.]+)/ | B61: UniversalActivityViewSet | C61: get:retrieve | D61: Yes | E61: ACT-003
A62: /api/alterations/ | B62: APIRootView | C62: (all methods) | D62: Yes | E62: AUTO-008
A63: /api/alterations/ | B63: AlterationRequestViewSet | C63: get:list, post:create | D63: Yes | E63: AUTO-008
A64: /api/alterations/(?P<pk>[/.]+)/ | B64: AlterationRequestViewSet | C64: get:retrieve | D64: Yes | E64: AUTO-008
A65: /api/alterations/(?P<pk>[/.]+)/approve/ | B65: AlterationRequestViewSet | C65: post:approve | D65: No | F65: Old alteration-request workflow. Its screen (AlterationsPanel.jsx) is not shown in the web app; alterations now run as orders (see Alterations / Orders rows).
A66: /api/alterations/(?P<pk>[/.]+)/assign/ | B66: AlterationRequestViewSet | C66: post:assign | D66: No | F66: Old alteration-request workflow. Its screen (AlterationsPanel.jsx) is not shown in the web app; alterations now run as orders (see Alterations / Orders rows).
A67: /api/alterations/(?P<pk>[/.]+)/cancel/ | B67: AlterationRequestViewSet | C67: post:cancel | D67: No | F67: Old alteration-request workflow. Its screen (AlterationsPanel.jsx) is not shown in the web app; alterations now run as orders (see Alterations / Orders rows).
A68: /api/alterations/(?P<pk>[/.]+)/complete/ | B68: AlterationRequestViewSet | C68: post:complete | D68: No | F68: Old alteration-request workflow. Its screen (AlterationsPanel.jsx) is not shown in the web app; alterations now run as orders (see Alterations / Orders rows).
A69: /api/alterations/(?P<pk>[/.]+)/customer-approved/ | B69: AlterationRequestViewSet | C69: post:customer_approved | D69: No | F69: Old alteration-request workflow. Its screen (AlterationsPanel.jsx) is not shown in the web app; alterations now run as orders (see Alterations / Orders rows).
A70: /api/alterations/(?P<pk>[/.]+)/customer-rejected/ | B70: AlterationRequestViewSet | C70: post:customer_rejected | D70: No | F70: Old alteration-request workflow. Its screen (AlterationsPanel.jsx) is not shown in the web app; alterations now run as orders (see Alterations / Orders rows).
...
